<?xml version="1.0" ?>
<!-- =================================================================================== -->
<!-- |    This document was autogenerated by xacro from robot.xacro                    | -->
<!-- |    EDITING THIS FILE BY HAND IS NOT RECOMMENDED                                 | -->
<!-- =================================================================================== -->
<robot name="Unknown bot">
  <material name="red">
    <color rgba="1 0 0 1"/>
  </material>
  <material name="blue">
    <color rgba="0 0 1 1"/>
  </material>
  <material name="green">
    <color rgba="0 1 0 1"/>
  </material>
  <link name="world"/>
  <joint name="fixed" type="fixed">
    <origin rpy="0 0 0" xyz="0 0 2"/>
    <parent link="world"/>
    <child link="base_link"/>
  </joint>
  <link name="base_link">
    <inertial>
      <origin rpy="0 0 0" xyz="0 0 0"/>
      <mass value="1"/>
      <inertia ixx="0.1" ixy="0" ixz="0" iyy="0.1" iyz="0" izz="0.1"/>
    </inertial>
    <visual>
      <origin rpy="0 0 0" xyz="0 0 0"/>
      <geometry>
        <box size="0.6 0.3 0.15"/>
      </geometry>
      <material name="white">
        <color rgba="1 1 1 1"/>
      </material>
    </visual>
    <collision>
      <origin rpy="0 0 0" xyz="0 0 0"/>
      <geometry>
        <box size="0.6 0.3 0.15"/>
      </geometry>
    </collision>
  </link>
  <link name="shoulder_bl_link">
    <inertial>
      <origin rpy="0 0 0" xyz="0 0 0"/>
      <mass value="0.1"/>
      <inertia ixx="0.1" ixy="0" ixz="0" iyy="0.1" iyz="0" izz="0.1"/>
    </inertial>
    <visual>
      <origin rpy="0 0 0" xyz="0 0.05 0"/>
      <geometry>
        <box size="0.1 0.1 0.1"/>
      </geometry>
      <material name="red"/>
    </visual>
    <collision>
      <origin rpy="0 0 0" xyz="0 0.05 0"/>
      <geometry>
        <box size="0.1 0.1 0.1"/>
      </geometry>
    </collision>
  </link>
  <joint name="baseToShoulder_bl_joint" type="revolute">
    <origin xyz="-0.2 0.15 0"/>
    <parent link="base_link"/>
    <child link="shoulder_bl_link"/>
    <axis xyz="1 0 0"/>
    <limit effort="10" lower="-0.7853981633974483" upper="0.7853981633974483" velocity="10"/>
  </joint>
  <link name="thigh_bl_link">
    <inertial>
      <origin rpy="0 0 0" xyz="0 0 0"/>
      <mass value="0.15"/>
      <inertia ixx="0.1" ixy="0" ixz="0" iyy="0.1" iyz="0" izz="0.1"/>
    </inertial>
    <visual>
      <origin rpy="0 0 0" xyz="0 0.05 -0.05"/>
      <geometry>
        <box size="0.1 0.1 0.2"/>
      </geometry>
      <material name="green"/>
    </visual>
    <collision>
      <origin rpy="0 0 0" xyz="0 0.05 -0.05"/>
      <geometry>
        <box size="0.1 0.1 0.2"/>
      </geometry>
    </collision>
  </link>
  <joint name="shoulderToThigh_bl_joint" type="revolute">
    <origin rpy="0 0.5 0" xyz="0 0.1 0"/>
    <parent link="shoulder_bl_link"/>
    <child link="thigh_bl_link"/>
    <axis xyz="0 1 0"/>
    <limit effort="10" lower="-3.14" upper="3.14" velocity="10"/>
  </joint>
  <link name="tibia_bl_link">
    <inertial>
      <origin rpy="0 0 0" xyz="0 0 0"/>
      <mass value="0.15"/>
      <inertia ixx="0.1" ixy="0" ixz="0" iyy="0.1" iyz="0" izz="0.1"/>
    </inertial>
    <visual>
      <origin rpy="0 0 0" xyz="0 0 -0.125"/>
      <geometry>
        <box size="0.1 0.1 0.25"/>
      </geometry>
      <material name="blue"/>
    </visual>
    <collision>
      <origin rpy="0 0 0" xyz="0 0 -0.125"/>
      <geometry>
        <box size="0.1 0.1 0.25"/>
      </geometry>
    </collision>
  </link>
  <joint name="tighToTibia_bl_joint" type="revolute">
    <origin rpy="0 -0.77 0" xyz="0 0.05 -0.15"/>
    <parent link="thigh_bl_link"/>
    <child link="tibia_bl_link"/>
    <axis xyz="0 1 0"/>
    <limit effort="10" lower="-3.14" upper="3.14" velocity="10"/>
  </joint>
  <link name="shoulder_br_link">
    <inertial>
      <origin rpy="0 0 0" xyz="0 0 0"/>
      <mass value="0.1"/>
      <inertia ixx="0.1" ixy="0" ixz="0" iyy="0.1" iyz="0" izz="0.1"/>
    </inertial>
    <visual>
      <origin rpy="0 0 0" xyz="0 -0.05 0"/>
      <geometry>
        <box size="0.1 0.1 0.1"/>
      </geometry>
      <material name="red"/>
    </visual>
    <collision>
      <origin rpy="0 0 0" xyz="0 -0.05 0"/>
      <geometry>
        <box size="0.1 0.1 0.1"/>
      </geometry>
    </collision>
  </link>
  <joint name="baseToShoulder_br_joint" type="revolute">
    <origin xyz="-0.2 -0.15 0"/>
    <parent link="base_link"/>
    <child link="shoulder_br_link"/>
    <axis xyz="1 0 0"/>
    <limit effort="10" lower="-0.7853981633974483" upper="0.7853981633974483" velocity="10"/>
  </joint>
  <link name="thigh_br_link">
    <inertial>
      <origin rpy="0 0 0" xyz="0 0 0"/>
      <mass value="0.15"/>
      <inertia ixx="0.1" ixy="0" ixz="0" iyy="0.1" iyz="0" izz="0.1"/>
    </inertial>
    <visual>
      <origin rpy="0 0 0" xyz="0 -0.05 -0.05"/>
      <geometry>
        <box size="0.1 0.1 0.2"/>
      </geometry>
      <material name="green"/>
    </visual>
    <collision>
      <origin rpy="0 0 0" xyz="0 -0.05 -0.05"/>
      <geometry>
        <box size="0.1 0.1 0.2"/>
      </geometry>
    </collision>
  </link>
  <joint name="shoulderToThigh_br_joint" type="revolute">
    <origin rpy="0 0.5 0" xyz="0 -0.1 0"/>
    <parent link="shoulder_br_link"/>
    <child link="thigh_br_link"/>
    <axis xyz="0 1 0"/>
    <limit effort="10" lower="-3.14" upper="3.14" velocity="10"/>
  </joint>
  <link name="tibia_br_link">
    <inertial>
      <origin rpy="0 0 0" xyz="0 0 0"/>
      <mass value="0.15"/>
      <inertia ixx="0.1" ixy="0" ixz="0" iyy="0.1" iyz="0" izz="0.1"/>
    </inertial>
    <visual>
      <origin rpy="0 0 0" xyz="0 0 -0.125"/>
      <geometry>
        <box size="0.1 0.1 0.25"/>
      </geometry>
      <material name="blue"/>
    </visual>
    <collision>
      <origin rpy="0 0 0" xyz="0 0 -0.125"/>
      <geometry>
        <box size="0.1 0.1 0.25"/>
      </geometry>
    </collision>
  </link>
  <joint name="tighToTibia_br_joint" type="revolute">
    <origin rpy="0 -0.77 0" xyz="0 -0.05 -0.15"/>
    <parent link="thigh_br_link"/>
    <child link="tibia_br_link"/>
    <axis xyz="0 1 0"/>
    <limit effort="10" lower="-3.14" upper="3.14" velocity="10"/>
  </joint>
  <link name="shoulder_fl_link">
    <inertial>
      <origin rpy="0 0 0" xyz="0 0 0"/>
      <mass value="0.1"/>
      <inertia ixx="0.1" ixy="0" ixz="0" iyy="0.1" iyz="0" izz="0.1"/>
    </inertial>
    <visual>
      <origin rpy="0 0 0" xyz="0 0.05 0"/>
      <geometry>
        <box size="0.1 0.1 0.1"/>
      </geometry>
      <material name="red"/>
    </visual>
    <collision>
      <origin rpy="0 0 0" xyz="0 0.05 0"/>
      <geometry>
        <box size="0.1 0.1 0.1"/>
      </geometry>
    </collision>
  </link>
  <joint name="baseToShoulder_fl_joint" type="revolute">
    <origin xyz="0.2 0.15 0"/>
    <parent link="base_link"/>
    <child link="shoulder_fl_link"/>
    <axis xyz="1 0 0"/>
    <limit effort="10" lower="-0.7853981633974483" upper="0.7853981633974483" velocity="10"/>
  </joint>
  <link name="thigh_fl_link">
    <inertial>
      <origin rpy="0 0 0" xyz="0 0 0"/>
      <mass value="0.15"/>
      <inertia ixx="0.1" ixy="0" ixz="0" iyy="0.1" iyz="0" izz="0.1"/>
    </inertial>
    <visual>
      <origin rpy="0 0 0" xyz="0 0.05 -0.05"/>
      <geometry>
        <box size="0.1 0.1 0.2"/>
      </geometry>
      <material name="green"/>
    </visual>
    <collision>
      <origin rpy="0 0 0" xyz="0 0.05 -0.05"/>
      <geometry>
        <box size="0.1 0.1 0.2"/>
      </geometry>
    </collision>
  </link>
  <joint name="shoulderToThigh_fl_joint" type="revolute">
    <origin rpy="0 0.5 0" xyz="0 0.1 0"/>
    <parent link="shoulder_fl_link"/>
    <child link="thigh_fl_link"/>
    <axis xyz="0 1 0"/>
    <limit effort="10" lower="-3.14" upper="3.14" velocity="10"/>
  </joint>
  <link name="tibia_fl_link">
    <inertial>
      <origin rpy="0 0 0" xyz="0 0 0"/>
      <mass value="0.15"/>
      <inertia ixx="0.1" ixy="0" ixz="0" iyy="0.1" iyz="0" izz="0.1"/>
    </inertial>
    <visual>
      <origin rpy="0 0 0" xyz="0 0 -0.125"/>
      <geometry>
        <box size="0.1 0.1 0.25"/>
      </geometry>
      <material name="blue"/>
    </visual>
    <collision>
      <origin rpy="0 0 0" xyz="0 0 -0.125"/>
      <geometry>
        <box size="0.1 0.1 0.25"/>
      </geometry>
    </collision>
  </link>
  <joint name="tighToTibia_fl_joint" type="revolute">
    <origin rpy="0 -0.77 0" xyz="0 0.05 -0.15"/>
    <parent link="thigh_fl_link"/>
    <child link="tibia_fl_link"/>
    <axis xyz="0 1 0"/>
    <limit effort="10" lower="-3.14" upper="3.14" velocity="10"/>
  </joint>
  <link name="shoulder_fr_link">
    <inertial>
      <origin rpy="0 0 0" xyz="0 0 0"/>
      <mass value="0.1"/>
      <inertia ixx="0.1" ixy="0" ixz="0" iyy="0.1" iyz="0" izz="0.1"/>
    </inertial>
    <visual>
      <origin rpy="0 0 0" xyz="0 -0.05 0"/>
      <geometry>
        <box size="0.1 0.1 0.1"/>
      </geometry>
      <material name="red"/>
    </visual>
    <collision>
      <origin rpy="0 0 0" xyz="0 -0.05 0"/>
      <geometry>
        <box size="0.1 0.1 0.1"/>
      </geometry>
    </collision>
  </link>
  <joint name="baseToShoulder_fr_joint" type="revolute">
    <origin xyz="0.2 -0.15 0"/>
    <parent link="base_link"/>
    <child link="shoulder_fr_link"/>
    <axis xyz="1 0 0"/>
    <limit effort="10" lower="-0.7853981633974483" upper="0.7853981633974483" velocity="10"/>
  </joint>
  <link name="thigh_fr_link">
    <inertial>
      <origin rpy="0 0 0" xyz="0 0 0"/>
      <mass value="0.15"/>
      <inertia ixx="0.1" ixy="0" ixz="0" iyy="0.1" iyz="0" izz="0.1"/>
    </inertial>
    <visual>
      <origin rpy="0 0 0" xyz="0 -0.05 -0.05"/>
      <geometry>
        <box size="0.1 0.1 0.2"/>
      </geometry>
      <material name="green"/>
    </visual>
    <collision>
      <origin rpy="0 0 0" xyz="0 -0.05 -0.05"/>
      <geometry>
        <box size="0.1 0.1 0.2"/>
      </geometry>
    </collision>
  </link>
  <joint name="shoulderToThigh_fr_joint" type="revolute">
    <origin rpy="0 0.5 0" xyz="0 -0.1 0"/>
    <parent link="shoulder_fr_link"/>
    <child link="thigh_fr_link"/>
    <axis xyz="0 1 0"/>
    <limit effort="10" lower="-3.14" upper="3.14" velocity="10"/>
  </joint>
  <link name="tibia_fr_link">
    <inertial>
      <origin rpy="0 0 0" xyz="0 0 0"/>
      <mass value="0.15"/>
      <inertia ixx="0.1" ixy="0" ixz="0" iyy="0.1" iyz="0" izz="0.1"/>
    </inertial>
    <visual>
      <origin rpy="0 0 0" xyz="0 0 -0.125"/>
      <geometry>
        <box size="0.1 0.1 0.25"/>
      </geometry>
      <material name="blue"/>
    </visual>
    <collision>
      <origin rpy="0 0 0" xyz="0 0 -0.125"/>
      <geometry>
        <box size="0.1 0.1 0.25"/>
      </geometry>
    </collision>
  </link>
  <joint name="tighToTibia_fr_joint" type="revolute">
    <origin rpy="0 -0.77 0" xyz="0 -0.05 -0.15"/>
    <parent link="thigh_fr_link"/>
    <child link="tibia_fr_link"/>
    <axis xyz="0 1 0"/>
    <limit effort="10" lower="-3.14" upper="3.14" velocity="10"/>
  </joint>
</robot>
